2023-11-10 11:58:41,024 INFO: Microblog startup [in /home/can/Documents/GitHub/flask-example/microblog/app/__init__.py:41]
2023-11-10 11:59:13,920 INFO: Microblog startup [in /home/can/Documents/GitHub/flask-example/microblog/app/__init__.py:41]
2023-11-10 11:59:23,858 INFO: Microblog startup [in /home/can/Documents/GitHub/flask-example/microblog/app/__init__.py:41]
2023-11-10 12:19:28,225 INFO: Microblog startup [in /home/can/Documents/GitHub/flask-example/microblog/app/__init__.py:41]
2023-11-10 12:19:41,518 INFO: Microblog startup [in /home/can/Documents/GitHub/flask-example/microblog/app/__init__.py:41]
2023-11-10 13:11:48,896 INFO: Microblog startup [in /home/can/Documents/GitHub/flask-example/microblog/app/__init__.py:41]
2023-11-10 13:12:31,140 INFO: Microblog startup [in /home/can/Documents/GitHub/flask-example/microblog/app/__init__.py:41]
2023-11-10 13:13:47,592 INFO: Microblog startup [in /home/can/Documents/GitHub/flask-example/microblog/app/__init__.py:41]
2023-11-10 13:23:05,516 INFO: Microblog startup [in /home/can/Documents/GitHub/flask-example/microblog/app/__init__.py:41]
2023-11-10 13:23:07,490 ERROR: Exception on /index [GET] [in /home/can/Desktop/microblog/venv/lib/python3.10/site-packages/flask/app.py:825]
Traceback (most recent call last):
  File "/home/can/Desktop/microblog/venv/lib/python3.10/site-packages/flask/app.py", line 1455, in wsgi_app
    response = self.full_dispatch_request()
  File "/home/can/Desktop/microblog/venv/lib/python3.10/site-packages/flask/app.py", line 869, in full_dispatch_request
    rv = self.handle_user_exception(e)
  File "/home/can/Desktop/microblog/venv/lib/python3.10/site-packages/flask/app.py", line 867, in full_dispatch_request
    rv = self.dispatch_request()
  File "/home/can/Desktop/microblog/venv/lib/python3.10/site-packages/flask/app.py", line 852, in dispatch_request
    return self.ensure_sync(self.view_functions[rule.endpoint])(**view_args)
  File "/home/can/Desktop/microblog/venv/lib/python3.10/site-packages/flask_login/utils.py", line 290, in decorated_view
    return current_app.ensure_sync(func)(*args, **kwargs)
  File "/home/can/Documents/GitHub/flask-example/microblog/app/routes.py", line 21, in index
    posts = current_user.followed_posts().paginate(page=page, per_page=app.config[POSTS_PER_PAGE], error_out=False)
NameError: name 'POSTS_PER_PAGE' is not defined
2023-11-10 13:23:10,425 ERROR: Exception on /index [GET] [in /home/can/Desktop/microblog/venv/lib/python3.10/site-packages/flask/app.py:825]
Traceback (most recent call last):
  File "/home/can/Desktop/microblog/venv/lib/python3.10/site-packages/flask/app.py", line 1455, in wsgi_app
    response = self.full_dispatch_request()
  File "/home/can/Desktop/microblog/venv/lib/python3.10/site-packages/flask/app.py", line 869, in full_dispatch_request
    rv = self.handle_user_exception(e)
  File "/home/can/Desktop/microblog/venv/lib/python3.10/site-packages/flask/app.py", line 867, in full_dispatch_request
    rv = self.dispatch_request()
  File "/home/can/Desktop/microblog/venv/lib/python3.10/site-packages/flask/app.py", line 852, in dispatch_request
    return self.ensure_sync(self.view_functions[rule.endpoint])(**view_args)
  File "/home/can/Desktop/microblog/venv/lib/python3.10/site-packages/flask_login/utils.py", line 290, in decorated_view
    return current_app.ensure_sync(func)(*args, **kwargs)
  File "/home/can/Documents/GitHub/flask-example/microblog/app/routes.py", line 21, in index
    posts = current_user.followed_posts().paginate(page=page, per_page=app.config[POSTS_PER_PAGE], error_out=False)
NameError: name 'POSTS_PER_PAGE' is not defined
2023-11-10 13:23:11,470 ERROR: Exception on /index [GET] [in /home/can/Desktop/microblog/venv/lib/python3.10/site-packages/flask/app.py:825]
Traceback (most recent call last):
  File "/home/can/Desktop/microblog/venv/lib/python3.10/site-packages/flask/app.py", line 1455, in wsgi_app
    response = self.full_dispatch_request()
  File "/home/can/Desktop/microblog/venv/lib/python3.10/site-packages/flask/app.py", line 869, in full_dispatch_request
    rv = self.handle_user_exception(e)
  File "/home/can/Desktop/microblog/venv/lib/python3.10/site-packages/flask/app.py", line 867, in full_dispatch_request
    rv = self.dispatch_request()
  File "/home/can/Desktop/microblog/venv/lib/python3.10/site-packages/flask/app.py", line 852, in dispatch_request
    return self.ensure_sync(self.view_functions[rule.endpoint])(**view_args)
  File "/home/can/Desktop/microblog/venv/lib/python3.10/site-packages/flask_login/utils.py", line 290, in decorated_view
    return current_app.ensure_sync(func)(*args, **kwargs)
  File "/home/can/Documents/GitHub/flask-example/microblog/app/routes.py", line 21, in index
    posts = current_user.followed_posts().paginate(page=page, per_page=app.config[POSTS_PER_PAGE], error_out=False)
NameError: name 'POSTS_PER_PAGE' is not defined
2023-11-10 13:24:06,367 INFO: Microblog startup [in /home/can/Documents/GitHub/flask-example/microblog/app/__init__.py:41]
2023-11-10 13:27:34,436 INFO: Microblog startup [in /home/can/Documents/GitHub/flask-example/microblog/app/__init__.py:41]
2023-11-10 13:27:56,335 INFO: Microblog startup [in /home/can/Documents/GitHub/flask-example/microblog/app/__init__.py:41]
2023-11-10 13:28:21,446 INFO: Microblog startup [in /home/can/Documents/GitHub/flask-example/microblog/app/__init__.py:41]
2023-11-10 13:28:37,200 INFO: Microblog startup [in /home/can/Documents/GitHub/flask-example/microblog/app/__init__.py:41]
2023-11-10 13:28:49,972 INFO: Microblog startup [in /home/can/Documents/GitHub/flask-example/microblog/app/__init__.py:41]
2023-11-10 13:32:50,986 INFO: Microblog startup [in /home/can/Documents/GitHub/flask-example/microblog/app/__init__.py:41]
2023-11-10 13:34:34,321 INFO: Microblog startup [in /home/can/Documents/GitHub/flask-example/microblog/app/__init__.py:41]
2023-11-10 13:45:06,709 INFO: Microblog startup [in /home/can/Documents/GitHub/flask-example/microblog/app/__init__.py:41]
2023-11-10 13:46:37,437 INFO: Microblog startup [in /home/can/Documents/GitHub/flask-example/microblog/app/__init__.py:41]
2023-11-11 03:40:12,840 INFO: Microblog startup [in /home/can/Documents/GitHub/flask-example/microblog/app/__init__.py:43]
2023-11-11 12:12:00,707 INFO: Microblog startup [in /home/can/Documents/GitHub/flask-example/microblog/app/__init__.py:43]
2023-11-11 12:12:37,443 ERROR: Exception on /reset_password_request [POST] [in /home/can/Desktop/microblog/venv/lib/python3.10/site-packages/flask/app.py:825]
Traceback (most recent call last):
  File "/home/can/Desktop/microblog/venv/lib/python3.10/site-packages/flask/app.py", line 1455, in wsgi_app
    response = self.full_dispatch_request()
  File "/home/can/Desktop/microblog/venv/lib/python3.10/site-packages/flask/app.py", line 869, in full_dispatch_request
    rv = self.handle_user_exception(e)
  File "/home/can/Desktop/microblog/venv/lib/python3.10/site-packages/flask/app.py", line 867, in full_dispatch_request
    rv = self.dispatch_request()
  File "/home/can/Desktop/microblog/venv/lib/python3.10/site-packages/flask/app.py", line 852, in dispatch_request
    return self.ensure_sync(self.view_functions[rule.endpoint])(**view_args)
  File "/home/can/Documents/GitHub/flask-example/microblog/app/routes.py", line 165, in reset_password_request
    send_password_reset_email(user)
  File "/home/can/Documents/GitHub/flask-example/microblog/app/email.py", line 14, in send_password_reset_email
    send_email('[Microblog] Reset Your Password',
  File "/home/can/Documents/GitHub/flask-example/microblog/app/email.py", line 10, in send_email
    mail.send(msg)
  File "/home/can/Desktop/microblog/venv/lib/python3.10/site-packages/flask_mail.py", line 491, in send
    with self.connect() as connection:
  File "/home/can/Desktop/microblog/venv/lib/python3.10/site-packages/flask_mail.py", line 144, in __enter__
    self.host = self.configure_host()
  File "/home/can/Desktop/microblog/venv/lib/python3.10/site-packages/flask_mail.py", line 165, in configure_host
    host.login(self.mail.username, self.mail.password)
  File "/usr/lib/python3.10/smtplib.py", line 750, in login
    raise last_exception
  File "/usr/lib/python3.10/smtplib.py", line 739, in login
    (code, resp) = self.auth(
  File "/usr/lib/python3.10/smtplib.py", line 662, in auth
    raise SMTPAuthenticationError(code, resp)
smtplib.SMTPAuthenticationError: (535, b'5.7.8 Username and Password not accepted. Learn more at\n5.7.8  https://support.google.com/mail/?p=BadCredentials g4-20020ac870c4000000b004181e5a724csm622200qtp.88 - gsmtp')
2023-11-11 12:16:16,806 INFO: Microblog startup [in /home/can/Documents/GitHub/flask-example/microblog/app/__init__.py:43]
2023-11-11 12:35:07,577 INFO: Microblog startup [in /home/can/Documents/GitHub/flask-example/microblog/app/__init__.py:43]
2023-11-11 12:55:04,946 INFO: Microblog startup [in /home/can/Documents/GitHub/flask-example/microblog/app/__init__.py:45]
2023-11-11 13:39:14,783 INFO: Microblog startup [in /home/can/Documents/GitHub/flask-example/microblog/app/__init__.py:45]
2023-11-11 13:44:56,259 INFO: Microblog startup [in /home/can/Documents/GitHub/flask-example/microblog/app/__init__.py:45]
2023-11-11 13:52:59,455 INFO: Microblog startup [in /home/can/Documents/GitHub/flask-example/microblog/app/__init__.py:47]
